<mujoco model="static">
  <option iterations="50" timestep="0.001" solver="PGS" gravity="0 0 -9.81" />

  <compiler angle="radian" meshdir="meshes" eulerseq="zyx" autolimits="true" />

  <default>
    <joint limited="true" damping="0.01" armature="0.01" frictionloss="0.01" />
    <geom condim="4" contype="1" conaffinity="15" friction="0.9 0.2 0.2" solref="0.001 2" />
    <motor ctrllimited="true" />
    <equality solref="0.001 2" />
    <default class="visualgeom">
      <geom material="visualgeom" condim="1" contype="0" conaffinity="0" />
    </default>
  </default>

  <asset>
    <mesh name="table"     content_type="model/stl" file="workcell/table.STL"    scale="0.001 0.001 0.001" />
    <mesh name="base_link" content_type="model/stl" file="piper/base_link.STL" />
    <mesh name="link1"     content_type="model/stl" file="piper/link1.STL" />
    <mesh name="link2"     content_type="model/stl" file="piper/link2.STL" />
    <mesh name="link3"     content_type="model/stl" file="piper/link3.STL" />
    <mesh name="link4"     content_type="model/stl" file="piper/link4.STL" />
    <mesh name="link5"     content_type="model/stl" file="piper/link5.STL" />
    <mesh name="link6_1"   content_type="model/stl" file="piper/link6_1.STL" />
    <mesh name="link7"     content_type="model/stl" file="piper/link7.STL" />
    <mesh name="link8"     content_type="model/stl" file="piper/link8.STL" />
<texture name="texplane" type="2d" builtin="checker" rgb1=".0 .0 .0" rgb2=".8 .8 .8" width="100" height="100" />
    <material name="matplane" reflectance="0." texture="texplane" texrepeat="1 1" texuniform="true" />
    <material name="visualgeom" rgba="0.5 0.9 0.2 1" />
  </asset>

  <worldbody>
    <light directional="true" diffuse="0.4 0.4 0.4" specular="0.1 0.1 0.1" pos="0 0 5.0" dir="0 0 -1" castshadow="false" />
    <light directional="true" diffuse="0.6 0.6 0.6" specular="0.2 0.2 0.2" pos="0 0 4" dir="0 0 -1" />
    <geom name="ground" type="plane" pos="0 0 0" size="100 100 0.001" quat="1 0 0 0" material="matplane" condim="3" conaffinity="15" />
    <camera name="fixed" pos="0 -3.0 0.6490221648764731" xyaxes="1 0 0 0 0 1" />
    <camera name="track" mode="trackcom" pos="0 -3.0 0.6490221648764731" xyaxes="1 0 0 0 0 1" />
    <body name="root" pos="0 0 0.14902216487647313" quat="1 0 0 0">
      <freejoint name="root" />
      <site name="imu" size="0.01" pos="0 0 0" />
      <geom pos="0.13 0.3 0.8" quat="1 0 0 0" type="mesh" rgba="0.792157 0.819608 0.933333 1" mesh="base_link" contype="1" conaffinity="0" density="0" group="1" class="visualgeom" />
      <geom type="mesh" rgba="0.792157 0.819608 0.933333 1" mesh="base_link" pos="0.13 0.3 0.8" quat="1 0 0 0" />
      <geom pos="0.13 -0.3 0.8" quat="1 0 0 0" type="mesh" rgba="0.792157 0.819608 0.933333 1" mesh="base_link" contype="1" conaffinity="0" density="0" group="1" class="visualgeom" />
      <geom type="mesh" rgba="0.792157 0.819608 0.933333 1" mesh="base_link" pos="0.13 -0.3 0.8" quat="1 0 0 0" />
      <geom pos="0 0.75 0" quat="0.707388 0.706825 0 0" type="mesh" rgba="0.6 0.6 0.6 1" mesh="table" contype="1" conaffinity="0" density="0" group="1" class="visualgeom" />
      <geom type="mesh" rgba="0.6 0.6 0.6 1" mesh="table" pos="0 0.75 0" quat="0.707388 0.706825 0 0" />
      <body name="left_link1" pos="0.13 0.3 0.923" quat="0.707105 0 0 -0.707108">
        <inertial pos="0.00131676 0.000310289 -0.00922875" quat="0.557105 0.432155 0.377373 0.600388" mass="0.097868" diaginertia="9.25942e-05 8.3083e-05 7.69469e-05" />
        <joint name="left_joint1" pos="0 0 0" axis="0 0 1" range="-2.618 2.618" actuatorfrcrange="-100 100" />
        <geom type="mesh" rgba="0.792157 0.819608 0.933333 1" mesh="link1" contype="1" conaffinity="0" density="0" group="1" class="visualgeom" />
        <geom type="mesh" rgba="0.792157 0.819608 0.933333 1" mesh="link1" />
        <body name="left_link2" quat="0.499998 0.5 -0.500002 -0.5">
          <inertial pos="0.148794 -0.00242027 0.00175155" quat="-0.0249063 0.70684 0.00803509 0.706889" mass="0.290889" diaginertia="0.00177549 0.00173142 0.00014552" />
          <joint name="left_joint2" pos="0 0 0" axis="0 0 1" range="0 3.14" actuatorfrcrange="-100 100" />
          <geom type="mesh" rgba="0.792157 0.819608 0.933333 1" mesh="link2" contype="1" conaffinity="0" density="0" group="1" class="visualgeom" />
          <geom type="mesh" rgba="0.792157 0.819608 0.933333 1" mesh="link2" />
          <body name="left_link3" pos="0.28358 0.028726 0" quat="0.998726 0 0 0.0504536">
            <inertial pos="-0.0996835 0.0349477 0.000508026" quat="0.0777021 0.702287 -0.0990541 0.700674" mass="0.290848" diaginertia="0.000241946 0.000222224 0.000100384" />
            <joint name="left_joint3" pos="0 0 0" axis="0 0 1" range="-2.697 0" actuatorfrcrange="-100 100" />
            <geom type="mesh" rgba="0.792157 0.819608 0.933333 1" mesh="link3" contype="1" conaffinity="0" density="0" group="1" class="visualgeom" />
            <geom type="mesh" rgba="0.792157 0.819608 0.933333 1" mesh="link3" />
            <body name="left_link4" pos="-0.24221 0.068514 0" quat="0.544767 -0.544769 -0.450809 0.450808">
              <inertial pos="0.000276465 -0.00102804 -0.00472831" quat="0.492305 0.505285 0.503294 0.499017" mass="0.127087" diaginertia="4.87057e-05 4.10595e-05 3.82001e-05" />
              <joint name="left_joint4" pos="0 0 0" axis="0 0 1" range="-1.832 1.832" actuatorfrcrange="-100 100" />
              <geom type="mesh" rgba="0.792157 0.819608 0.933333 1" mesh="link4" contype="1" conaffinity="0" density="0" group="1" class="visualgeom" />
              <geom type="mesh" rgba="0.792157 0.819608 0.933333 1" mesh="link4" />
              <body name="left_link5" quat="0.707105 0.707108 0 0">
                <inertial pos="8.82262e-05 0.0566829 -0.0019612" quat="0.507447 0.490986 0.506887 0.494466" mass="0.144711" diaginertia="5.63237e-05 4.88652e-05 4.39642e-05" />
                <joint name="left_joint5" pos="0 0 0" axis="0 0 1" range="-1.22 1.22" actuatorfrcrange="-100 100" />
                <geom type="mesh" rgba="0.792157 0.819608 0.933333 1" mesh="link5" contype="1" conaffinity="0" density="0" group="1" class="visualgeom" />
                <geom type="mesh" rgba="0.792157 0.819608 0.933333 1" mesh="link5" />
                <body name="left_link6" pos="0 0.091 0.0014165" quat="1.89468e-08 -1.89469e-08 -0.707105 -0.707108">
                  <inertial pos="-0.0152786 -0.0063209 0.0258805" quat="-0.380723 0.691868 0.0857128 0.607471" mass="0.268187" diaginertia="0.00548634 0.0054459 0.00163474" />
                  <joint name="left_joint6" pos="0 0 0" axis="0 0 1" range="-3.14 3.14" actuatorfrcrange="-100 100" />
                  <geom type="mesh" rgba="0.792157 0.819608 0.933333 1" mesh="link6_1" contype="1" conaffinity="0" density="0" group="1" class="visualgeom" />
                  <geom type="mesh" rgba="0.792157 0.819608 0.933333 1" mesh="link6_1" />
                  <geom size="0.0115 0.021 0.021" pos="-0.064554 0 0.050443" quat="0.900447 0 -0.434966 0" type="box" contype="1" conaffinity="0" density="0" group="1" class="visualgeom" />
                  <geom type="box" rgba="" size="0.0115 0.021 0.021" pos="-0.064554 0 0.050443" quat="0.900447 0 -0.434966 0" />
                  <body name="left_link7.1" pos="0 0 0.13503" quat="1.89468e-08 1.89469e-08 0.707108 0.707105">
                    <inertial pos="-0.000277778 -0.0467673 -0.00921029" quat="0.46134 0.536174 -0.553273 0.439968" mass="0.0264823" diaginertia="1.45134e-05 1.00041e-05 5.87021e-06" />
                    <joint name="left_joint7.1" pos="0 0 0" axis="0 0 -1" type="slide" range="0 0.04" actuatorfrcrange="-10 10" />
                    <geom type="mesh" rgba="0.792157 0.819608 0.933333 1" mesh="link7" contype="1" conaffinity="0" density="0" group="1" class="visualgeom" />
                    <geom type="mesh" rgba="0.792157 0.819608 0.933333 1" mesh="link7" />
                  </body>
                  <body name="left_link7.2" pos="0 0 0.13503" quat="1.89468e-08 -1.89469e-08 -0.707108 0.707105">
                    <inertial pos="0.000277817 0.0467674 -0.0092103" quat="0.553273 0.439968 -0.46134 0.536174" mass="0.0264822" diaginertia="1.45133e-05 1.0004e-05 5.87021e-06" />
                    <joint name="left_joint7.2" pos="0 0 0" axis="0 0 1" type="slide" range="-0.04 0" actuatorfrcrange="-10 10" />
                    <geom type="mesh" rgba="0.792157 0.819608 0.933333 1" mesh="link8" contype="1" conaffinity="0" density="0" group="1" class="visualgeom" />
                    <geom type="mesh" rgba="0.792157 0.819608 0.933333 1" mesh="link8" />
                  </body>
                </body>
              </body>
            </body>
          </body>
        </body>
      </body>
      <body name="right_link1" pos="0.13 -0.3 0.923" quat="0.707105 0 0 -0.707108">
        <inertial pos="0.00131676 0.000310289 -0.00922875" quat="0.557105 0.432155 0.377373 0.600388" mass="0.097868" diaginertia="9.25942e-05 8.3083e-05 7.69469e-05" />
        <joint name="right_joint1" pos="0 0 0" axis="0 0 1" range="-2.618 2.618" actuatorfrcrange="-100 100" />
        <geom type="mesh" rgba="0.792157 0.819608 0.933333 1" mesh="link1" contype="1" conaffinity="0" density="0" group="1" class="visualgeom" />
        <geom type="mesh" rgba="0.792157 0.819608 0.933333 1" mesh="link1" />
        <body name="right_link2" quat="0.499998 0.5 -0.500002 -0.5">
          <inertial pos="0.148794 -0.00242027 0.00175155" quat="-0.0249063 0.70684 0.00803509 0.706889" mass="0.290889" diaginertia="0.00177549 0.00173142 0.00014552" />
          <joint name="right_joint2" pos="0 0 0" axis="0 0 1" range="0 3.14" actuatorfrcrange="-100 100" />
          <geom type="mesh" rgba="0.792157 0.819608 0.933333 1" mesh="link2" contype="1" conaffinity="0" density="0" group="1" class="visualgeom" />
          <geom type="mesh" rgba="0.792157 0.819608 0.933333 1" mesh="link2" />
          <body name="right_link3" pos="0.28358 0.028726 0" quat="0.998726 0 0 0.0504536">
            <inertial pos="-0.0996835 0.0349477 0.000508026" quat="0.0777021 0.702287 -0.0990541 0.700674" mass="0.290848" diaginertia="0.000241946 0.000222224 0.000100384" />
            <joint name="right_joint3" pos="0 0 0" axis="0 0 1" range="-2.697 0" actuatorfrcrange="-100 100" />
            <geom type="mesh" rgba="0.792157 0.819608 0.933333 1" mesh="link3" contype="1" conaffinity="0" density="0" group="1" class="visualgeom" />
            <geom type="mesh" rgba="0.792157 0.819608 0.933333 1" mesh="link3" />
            <body name="right_link4" pos="-0.24221 0.068514 0" quat="0.544767 -0.544769 -0.450809 0.450808">
              <inertial pos="0.000276465 -0.00102804 -0.00472831" quat="0.492305 0.505285 0.503294 0.499017" mass="0.127087" diaginertia="4.87057e-05 4.10595e-05 3.82001e-05" />
              <joint name="right_joint4" pos="0 0 0" axis="0 0 1" range="-1.832 1.832" actuatorfrcrange="-100 100" />
              <geom type="mesh" rgba="0.792157 0.819608 0.933333 1" mesh="link4" contype="1" conaffinity="0" density="0" group="1" class="visualgeom" />
              <geom type="mesh" rgba="0.792157 0.819608 0.933333 1" mesh="link4" />
              <body name="right_link5" quat="0.707105 0.707108 0 0">
                <inertial pos="8.82262e-05 0.0566829 -0.0019612" quat="0.507447 0.490986 0.506887 0.494466" mass="0.144711" diaginertia="5.63237e-05 4.88652e-05 4.39642e-05" />
                <joint name="right_joint5" pos="0 0 0" axis="0 0 1" range="-1.22 1.22" actuatorfrcrange="-100 100" />
                <geom type="mesh" rgba="0.792157 0.819608 0.933333 1" mesh="link5" contype="1" conaffinity="0" density="0" group="1" class="visualgeom" />
                <geom type="mesh" rgba="0.792157 0.819608 0.933333 1" mesh="link5" />
                <body name="right_link6" pos="0 0.091 0.0014165" quat="1.89468e-08 -1.89469e-08 -0.707105 -0.707108">
                  <inertial pos="-0.0152786 -0.0063209 0.0258805" quat="-0.380723 0.691868 0.0857128 0.607471" mass="0.268187" diaginertia="0.00548634 0.0054459 0.00163474" />
                  <joint name="right_joint6" pos="0 0 0" axis="0 0 1" range="-3.14 3.14" actuatorfrcrange="-100 100" />
                  <geom type="mesh" rgba="0.792157 0.819608 0.933333 1" mesh="link6_1" contype="1" conaffinity="0" density="0" group="1" class="visualgeom" />
                  <geom type="mesh" rgba="0.792157 0.819608 0.933333 1" mesh="link6_1" />
                  <geom size="0.0115 0.021 0.021" pos="-0.064554 0 0.050443" quat="0.900447 0 -0.434966 0" type="box" contype="1" conaffinity="0" density="0" group="1" class="visualgeom" />
                  <geom type="box" rgba="" size="0.0115 0.021 0.021" pos="-0.064554 0 0.050443" quat="0.900447 0 -0.434966 0" />
                  <body name="right_link7.1" pos="0 0 0.13503" quat="1.89468e-08 1.89469e-08 0.707108 0.707105">
                    <inertial pos="-0.000277778 -0.0467673 -0.00921029" quat="0.46134 0.536174 -0.553273 0.439968" mass="0.0264823" diaginertia="1.45134e-05 1.00041e-05 5.87021e-06" />
                    <joint name="right_joint7.1" pos="0 0 0" axis="0 0 -1" type="slide" range="0 0.04" actuatorfrcrange="-10 10" />
                    <geom type="mesh" rgba="0.792157 0.819608 0.933333 1" mesh="link7" contype="1" conaffinity="0" density="0" group="1" class="visualgeom" />
                    <geom type="mesh" rgba="0.792157 0.819608 0.933333 1" mesh="link7" />
                  </body>
                  <body name="right_link7.2" pos="0 0 0.13503" quat="1.89468e-08 -1.89469e-08 -0.707108 0.707105">
                    <inertial pos="0.000277817 0.0467674 -0.0092103" quat="0.553273 0.439968 -0.46134 0.536174" mass="0.0264822" diaginertia="1.45133e-05 1.0004e-05 5.87021e-06" />
                    <joint name="right_joint7.2" pos="0 0 0" axis="0 0 1" type="slide" range="-0.04 0" actuatorfrcrange="-10 10" />
                    <geom type="mesh" rgba="0.792157 0.819608 0.933333 1" mesh="link8" contype="1" conaffinity="0" density="0" group="1" class="visualgeom" />
                    <geom type="mesh" rgba="0.792157 0.819608 0.933333 1" mesh="link8" />
                  </body>
                </body>
              </body>
            </body>
          </body>
        </body>
      </body>
    </body>
  </worldbody>

  <actuator>
    <motor name="left_joint1" joint="left_joint1" ctrllimited="true" ctrlrange="-100 100" gear="1" />
    <motor name="left_joint2" joint="left_joint2" ctrllimited="true" ctrlrange="-100 100" gear="1" />
    <motor name="left_joint3" joint="left_joint3" ctrllimited="true" ctrlrange="-100 100" gear="1" />
    <motor name="left_joint4" joint="left_joint4" ctrllimited="true" ctrlrange="-100 100" gear="1" />
    <motor name="left_joint5" joint="left_joint5" ctrllimited="true" ctrlrange="-100 100" gear="1" />
    <motor name="left_joint6" joint="left_joint6" ctrllimited="true" ctrlrange="-100 100" gear="1" />
    <motor name="left_joint7.1" joint="left_joint7.1" ctrllimited="true" ctrlrange="-10 10" gear="1" />
    <motor name="left_joint7.2" joint="left_joint7.2" ctrllimited="true" ctrlrange="-10 10" gear="1" />
    <motor name="right_joint1" joint="right_joint1" ctrllimited="true" ctrlrange="-100 100" gear="1" />
    <motor name="right_joint2" joint="right_joint2" ctrllimited="true" ctrlrange="-100 100" gear="1" />
    <motor name="right_joint3" joint="right_joint3" ctrllimited="true" ctrlrange="-100 100" gear="1" />
    <motor name="right_joint4" joint="right_joint4" ctrllimited="true" ctrlrange="-100 100" gear="1" />
    <motor name="right_joint5" joint="right_joint5" ctrllimited="true" ctrlrange="-100 100" gear="1" />
    <motor name="right_joint6" joint="right_joint6" ctrllimited="true" ctrlrange="-100 100" gear="1" />
    <motor name="right_joint7.1" joint="right_joint7.1" ctrllimited="true" ctrlrange="-10 10" gear="1" />
    <motor name="right_joint7.2" joint="right_joint7.2" ctrllimited="true" ctrlrange="-10 10" gear="1" />
  </actuator>

  <sensor>
    <actuatorpos name="left_joint1_p" actuator="left_joint1" />
    <actuatorvel name="left_joint1_v" actuator="left_joint1" />
    <actuatorfrc name="left_joint1_f" actuator="left_joint1" noise="0.001" />
    <actuatorpos name="left_joint2_p" actuator="left_joint2" />
    <actuatorvel name="left_joint2_v" actuator="left_joint2" />
    <actuatorfrc name="left_joint2_f" actuator="left_joint2" noise="0.001" />
    <actuatorpos name="left_joint3_p" actuator="left_joint3" />
    <actuatorvel name="left_joint3_v" actuator="left_joint3" />
    <actuatorfrc name="left_joint3_f" actuator="left_joint3" noise="0.001" />
    <actuatorpos name="left_joint4_p" actuator="left_joint4" />
    <actuatorvel name="left_joint4_v" actuator="left_joint4" />
    <actuatorfrc name="left_joint4_f" actuator="left_joint4" noise="0.001" />
    <actuatorpos name="left_joint5_p" actuator="left_joint5" />
    <actuatorvel name="left_joint5_v" actuator="left_joint5" />
    <actuatorfrc name="left_joint5_f" actuator="left_joint5" noise="0.001" />
    <actuatorpos name="left_joint6_p" actuator="left_joint6" />
    <actuatorvel name="left_joint6_v" actuator="left_joint6" />
    <actuatorfrc name="left_joint6_f" actuator="left_joint6" noise="0.001" />
    <actuatorpos name="left_joint7.1_p" actuator="left_joint7.1" />
    <actuatorvel name="left_joint7.1_v" actuator="left_joint7.1" />
    <actuatorfrc name="left_joint7.1_f" actuator="left_joint7.1" noise="0.001" />
    <actuatorpos name="left_joint7.2_p" actuator="left_joint7.2" />
    <actuatorvel name="left_joint7.2_v" actuator="left_joint7.2" />
    <actuatorfrc name="left_joint7.2_f" actuator="left_joint7.2" noise="0.001" />
    <actuatorpos name="right_joint1_p" actuator="right_joint1" />
    <actuatorvel name="right_joint1_v" actuator="right_joint1" />
    <actuatorfrc name="right_joint1_f" actuator="right_joint1" noise="0.001" />
    <actuatorpos name="right_joint2_p" actuator="right_joint2" />
    <actuatorvel name="right_joint2_v" actuator="right_joint2" />
    <actuatorfrc name="right_joint2_f" actuator="right_joint2" noise="0.001" />
    <actuatorpos name="right_joint3_p" actuator="right_joint3" />
    <actuatorvel name="right_joint3_v" actuator="right_joint3" />
    <actuatorfrc name="right_joint3_f" actuator="right_joint3" noise="0.001" />
    <actuatorpos name="right_joint4_p" actuator="right_joint4" />
    <actuatorvel name="right_joint4_v" actuator="right_joint4" />
    <actuatorfrc name="right_joint4_f" actuator="right_joint4" noise="0.001" />
    <actuatorpos name="right_joint5_p" actuator="right_joint5" />
    <actuatorvel name="right_joint5_v" actuator="right_joint5" />
    <actuatorfrc name="right_joint5_f" actuator="right_joint5" noise="0.001" />
    <actuatorpos name="right_joint6_p" actuator="right_joint6" />
    <actuatorvel name="right_joint6_v" actuator="right_joint6" />
    <actuatorfrc name="right_joint6_f" actuator="right_joint6" noise="0.001" />
    <actuatorpos name="right_joint7.1_p" actuator="right_joint7.1" />
    <actuatorvel name="right_joint7.1_v" actuator="right_joint7.1" />
    <actuatorfrc name="right_joint7.1_f" actuator="right_joint7.1" noise="0.001" />
    <actuatorpos name="right_joint7.2_p" actuator="right_joint7.2" />
    <actuatorvel name="right_joint7.2_v" actuator="right_joint7.2" />
    <actuatorfrc name="right_joint7.2_f" actuator="right_joint7.2" noise="0.001" />
    <framequat name="orientation" objtype="site" noise="0.001" objname="imu" />
    <gyro name="angular-velocity" site="imu" noise="0.005" cutoff="34.9" />
  </sensor>
</mujoco>