<?xml version="1.0" ?>
<robot name="static">
  <link name="world" />
  <link name="base" />
  <link name="center_cam" />
  <material name="table_grey">
    <color rgba="0.6 0.6 0.6 1.0" />
  </material>
  <link name="table_corner">
    <visual>
      <geometry>
        <mesh filename="{SIMS_CORE}/meshes/workcell/table.STL" scale="0.001 0.001 0.001" />
      </geometry>
      <material name="table_grey" />
    </visual>
    <collision>
      <geometry>
        <mesh filename="{SIMS_CORE}/meshes/workcell/table.STL" scale="0.001 0.001 0.001" />
      </geometry>
    </collision>
  </link>
  <joint name="world_to_base" type="fixed">
    <parent link="world" />
    <child link="base" />
    <origin rpy="0 0 0" xyz="0.13 0 0.8" />
  </joint>
  <joint name="world_to_table" type="fixed">
    <parent link="world" />
    <child link="table_corner" />
    <origin rpy="1.57 0 0" xyz="0 0.75 0" />
  </joint>
  <joint name="base_to_left_base" type="fixed">
    <parent link="base" />
    <child link="left_base_link" />
    <origin rpy="0 0 0" xyz="0 0.3 0" />
  </joint>
  <joint name="base_to_right_base" type="fixed">
    <parent link="base" />
    <child link="right_base_link" />
    <origin rpy="0 0 0" xyz="0 -0.3 0" />
  </joint>
  <ros2_control name="left_PiperHardwareSystem" type="system">
    <hardware>
      <plugin>mock_components/GenericSystem</plugin>
    </hardware>
    <joint name="left_joint1">
      <command_interface name="position" />
      <command_interface name="effort" />
      <command_interface name="velocity" />
      <state_interface name="position" />
      <state_interface name="effort" />
      <state_interface name="velocity" />
      <param name="min">-2.618</param>
      <param name="max">2.618</param>
      <param name="type">revolute</param>
      <param name="max_effort">100</param>
    </joint>
    <joint name="left_joint2">
      <command_interface name="position" />
      <command_interface name="effort" />
      <command_interface name="velocity" />
      <state_interface name="position" />
      <state_interface name="effort" />
      <state_interface name="velocity" />
      <param name="min">0</param>
      <param name="max">3.14</param>
      <param name="type">revolute</param>
      <param name="max_effort">100</param>
    </joint>
    <joint name="left_joint3">
      <command_interface name="position" />
      <command_interface name="effort" />
      <command_interface name="velocity" />
      <state_interface name="position" />
      <state_interface name="effort" />
      <state_interface name="velocity" />
      <param name="min">-2.697</param>
      <param name="max">0</param>
      <param name="type">revolute</param>
      <param name="max_effort">100</param>
    </joint>
    <joint name="left_joint4">
      <command_interface name="position" />
      <command_interface name="effort" />
      <command_interface name="velocity" />
      <state_interface name="position" />
      <state_interface name="effort" />
      <state_interface name="velocity" />
      <param name="min">-1.832</param>
      <param name="max">1.832</param>
      <param name="type">revolute</param>
      <param name="max_effort">100</param>
    </joint>
    <joint name="left_joint5">
      <command_interface name="position" />
      <command_interface name="effort" />
      <command_interface name="velocity" />
      <state_interface name="position" />
      <state_interface name="effort" />
      <state_interface name="velocity" />
      <param name="min">-1.22</param>
      <param name="max">1.22</param>
      <param name="type">revolute</param>
      <param name="max_effort">100</param>
    </joint>
    <joint name="left_joint6">
      <command_interface name="position" />
      <command_interface name="effort" />
      <command_interface name="velocity" />
      <state_interface name="position" />
      <state_interface name="effort" />
      <state_interface name="velocity" />
      <param name="min">-3.14</param>
      <param name="max">3.14</param>
      <param name="type">revolute</param>
      <param name="max_effort">100</param>
    </joint>
    <joint name="left_joint7.1">
      <command_interface name="position" />
      <command_interface name="effort" />
      <command_interface name="velocity" />
      <state_interface name="position" />
      <state_interface name="effort" />
      <state_interface name="velocity" />
      <param name="min">0</param>
      <param name="max">0.04</param>
      <param name="type">prismatic</param>
      <param name="max_effort">10</param>
    </joint>
    <joint name="left_joint7.2">
      <command_interface name="position" />
      <command_interface name="effort" />
      <command_interface name="velocity" />
      <state_interface name="position" />
      <state_interface name="effort" />
      <state_interface name="velocity" />
      <param name="min">-0.04</param>
      <param name="max">0</param>
      <param name="type">prismatic</param>
      <param name="max_effort">10</param>
    </joint>
  </ros2_control>
  <link name="left_base_link">
    <inertial>
      <origin rpy="0 0 0" xyz="-0.00979274765955341 1.82905827587138E-06 0.0410100126360189" />
      <mass value="0.162548567403693" />
      <inertia ixx="0.000226596924525071" ixy="-7.33972270153965E-08" ixz="2.13249977802622E-06" iyy="0.000269444772561524" iyz="8.15169009611054E-09" izz="0.000222318258878636" />
    </inertial>
    <visual>
      <origin rpy="0 0 0" xyz="0 0 0" />
      <geometry>
        <mesh filename="{SIMS_CORE}/meshes/piper/base_link.dae" />
      </geometry>
      <material name="">
        <color rgba="0.792156862745098 0.819607843137255 0.933333333333333 1" />
      </material>
    </visual>
    <collision>
      <origin rpy="0 0 0" xyz="0 0 0" />
      <geometry>
        <mesh filename="{SIMS_CORE}/meshes/piper/base_link.STL" />
      </geometry>
    </collision>
  </link>
  <link name="left_link1">
    <inertial>
      <origin rpy="0 0 0" xyz="0.00131676031927024 0.000310288842008612 -0.00922874512303437" />
      <mass value="0.0978679932242825" />
      <inertia ixx="7.76684558296782E-05" ixy="1.09084650459924E-07" ixz="-1.9748053243241E-06" iyy="9.24967780161547E-05" iyz="9.91284646834582E-07" izz="8.24589062407807E-05" />
    </inertial>
    <visual>
      <origin rpy="0 0 0" xyz="0 0 0" />
      <geometry>
        <mesh filename="{SIMS_CORE}/meshes/piper/link1.dae" />
      </geometry>
      <material name="">
        <color rgba="0.792156862745098 0.819607843137255 0.933333333333333 1" />
      </material>
    </visual>
    <collision>
      <origin rpy="0 0 0" xyz="0 0 0" />
      <geometry>
        <mesh filename="{SIMS_CORE}/meshes/piper/link1.STL" />
      </geometry>
    </collision>
  </link>
  <joint name="left_joint1" type="revolute">
    <origin rpy="0 0 -1.5708" xyz="0 0 0.123" />
    <parent link="left_base_link" />
    <child link="left_link1" />
    <axis xyz="0 0 1" />
    <limit effort="100" lower="-2.618" upper="2.618" velocity="3" />
  </joint>
  <link name="left_link2">
    <inertial>
      <origin rpy="0 0 0" xyz="0.148793602378802 -0.00242026983944119 0.00175154638467948" />
      <mass value="0.290888938633388" />
      <inertia ixx="0.000148959640166183" ixy="-7.37750384371657E-05" ixz="-9.68688405196236E-07" iyy="0.00172800946632652" iyz="-1.09692225564224E-06" izz="0.0017754628344594" />
    </inertial>
    <visual>
      <origin rpy="0 0 0" xyz="0 0 0" />
      <geometry>
        <mesh filename="{SIMS_CORE}/meshes/piper/link2.dae" />
      </geometry>
      <material name="">
        <color rgba="0.792156862745098 0.819607843137255 0.933333333333333 1" />
      </material>
    </visual>
    <collision>
      <origin rpy="0 0 0" xyz="0 0 0" />
      <geometry>
        <mesh filename="{SIMS_CORE}/meshes/piper/link2.STL" />
      </geometry>
    </collision>
  </link>
  <joint name="left_joint2" type="revolute">
    <origin rpy="1.5708 0 -1.5708" xyz="0 0 0" />
    <parent link="left_link1" />
    <child link="left_link2" />
    <axis xyz="0 0 1" />
    <limit effort="100" lower="0" upper="3.14" velocity="3" />
  </joint>
  <link name="left_link3">
    <inertial>
      <origin rpy="0 0 0" xyz="-0.0996835215213704 0.0349477226691318 0.000508025815507312" />
      <mass value="0.290847697793211" />
      <inertia ixx="0.000107879011637167" ixy="2.92669521203626E-05" ixz="6.825922326238E-07" iyy="0.000214751671792086" iyz="-7.78469047878196E-07" izz="0.000241923439340319" />
    </inertial>
    <visual>
      <origin rpy="0 0 0" xyz="0 0 0" />
      <geometry>
        <mesh filename="{SIMS_CORE}/meshes/piper/link3.dae" />
      </geometry>
      <material name="">
        <color rgba="0.792156862745098 0.819607843137255 0.933333333333333 1" />
      </material>
    </visual>
    <collision>
      <origin rpy="0 0 0" xyz="0 0 0" />
      <geometry>
        <mesh filename="{SIMS_CORE}/meshes/piper/link3.STL" />
      </geometry>
    </collision>
  </link>
  <joint name="left_joint3" type="revolute">
    <origin rpy="0 0 0.10095" xyz="0.28358 0.028726 0" />
    <parent link="left_link2" />
    <child link="left_link3" />
    <axis xyz="0 0 1" />
    <limit effort="100" lower="-2.697" upper="0" velocity="3" />
  </joint>
  <link name="left_link4">
    <inertial>
      <origin rpy="0 0 0" xyz="0.000276464622387979 -0.00102803669324875 -0.00472830700561663" />
      <mass value="0.127087348341362" />
      <inertia ixx="3.82011730423416E-05" ixy="-4.92358350897513E-08" ixz="4.89589432973119E-08" iyy="4.87048555222578E-05" iyz="6.70802942500512E-08" izz="4.10592077565559E-05" />
    </inertial>
    <visual>
      <origin rpy="0 0 0" xyz="0 0 0" />
      <geometry>
        <mesh filename="{SIMS_CORE}/meshes/piper/link4.dae" />
      </geometry>
      <material name="">
        <color rgba="0.792156862745098 0.819607843137255 0.933333333333333 1" />
      </material>
    </visual>
    <collision>
      <origin rpy="0 0 0" xyz="0 0 0" />
      <geometry>
        <mesh filename="{SIMS_CORE}/meshes/piper/link4.STL" />
      </geometry>
    </collision>
  </link>
  <joint name="left_joint4" type="revolute">
    <origin rpy="-1.5708 0 1.3826" xyz="-0.24221 0.068514 0" />
    <parent link="left_link3" />
    <child link="left_link4" />
    <axis xyz="0 0 1" />
    <limit effort="100" lower="-1.832" upper="1.832" velocity="3" />
  </joint>
  <link name="left_link5">
    <inertial>
      <origin rpy="0 0 0" xyz="8.82262433516967E-05 0.0566829014808256 -0.00196119720482461" />
      <mass value="0.144711242639457" />
      <inertia ixx="4.39644313662493E-05" ixy="-3.59259686444846E-08" ixz="-1.89747741386183E-08" iyy="5.63173920951307E-05" iyz="-2.1540716689785E-07" izz="4.88713664675268E-05" />
    </inertial>
    <visual>
      <origin rpy="0 0 0" xyz="0 0 0" />
      <geometry>
        <mesh filename="{SIMS_CORE}/meshes/piper/link5.dae" />
      </geometry>
      <material name="">
        <color rgba="0.792156862745098 0.819607843137255 0.933333333333333 1" />
      </material>
    </visual>
    <collision>
      <origin rpy="0 0 0" xyz="0 0 0" />
      <geometry>
        <mesh filename="{SIMS_CORE}/meshes/piper/link5.STL" />
      </geometry>
    </collision>
  </link>
  <joint name="left_joint5" type="revolute">
    <origin rpy="1.5708 0 0" xyz="0 0 0" />
    <parent link="left_link4" />
    <child link="left_link5" />
    <axis xyz="0 0 1" />
    <limit effort="100" lower="-1.22" upper="1.22" velocity="3" />
  </joint>
  <link name="left_link6">
    <inertial>
      <origin rpy="0 0 0" xyz="0.00103120214523473 0.0121761387587524 0.0315480874960164" />
      <mass value="0.195187143240719" />
      <inertia ixx="6.43790256535539E-05" ixy="-1.2366166157046E-06" ixz="1.97664606328472E-07" iyy="0.000126146396374301" iyz="2.41157078516408E-06" izz="0.000154087076816444" />
    </inertial>
    <visual>
      <origin rpy="0 0 1.5708" xyz="0 0 0" />
      <geometry>
        <mesh filename="{SIMS_CORE}/meshes/piper/link6.dae" />
      </geometry>
      <material name="">
        <color rgba="0.792156862745098 0.819607843137255 0.933333333333333 1" />
      </material>
    </visual>
    <collision>
      <origin rpy="0 0 0" xyz="0 0 0" />
      <geometry>
        <mesh filename="{SIMS_CORE}/meshes/piper/link6_1.STL" />
      </geometry>
    </collision>
  </link>
  <joint name="left_joint6" type="revolute">
    <origin rpy="-1.5708 -3.1415926 0" xyz="0 0.091 0.0014165" />
    <parent link="left_link5" />
    <child link="left_link6" />
    <axis xyz="0 0 1" />
    <limit effort="100" lower="-3.14" upper="3.14" velocity="3" />
  </joint>
  <link name="left_link7.1">
    <inertial>
      <origin rpy="0 0 0" xyz="-0.000277778383727112 -0.0467673043650824 -0.00921029491873201" />
      <mass value="0.02648229234527" />
      <inertia ixx="9.99787479924589E-06" ixy="-1.57548495096104E-07" ixz="-2.71342775003487E-08" iyy="6.1795212293655E-06" iyz="-1.58939803580081E-06" izz="1.42102717246564E-05" />
    </inertial>
    <visual>
      <origin rpy="0 0 0" xyz="0 0 0" />
      <geometry>
        <mesh filename="{SIMS_CORE}/meshes/piper/link7.dae" />
      </geometry>
      <material name="">
        <color rgba="0.792156862745098 0.819607843137255 0.933333333333333 1" />
      </material>
    </visual>
    <collision>
      <origin rpy="0 0 0" xyz="0 0 0" />
      <geometry>
        <mesh filename="{SIMS_CORE}/meshes/piper/link7.STL" />
      </geometry>
    </collision>
  </link>
  <joint name="left_joint7.1" type="prismatic">
    <origin rpy="1.5708 0 3.1415926" xyz="0 0 0.13503" />
    <parent link="left_link6" />
    <child link="left_link7.1" />
    <axis xyz="0 0 -1" />
    <limit effort="10" lower="0" upper="0.04" velocity="1" />
  </joint>
  <link name="left_link7.2">
    <inertial>
      <origin rpy="0 0 0" xyz="0.000277816920932317 0.0467673824063769 -0.00921030054508036" />
      <mass value="0.0264822021416248" />
      <inertia ixx="9.99779119357223E-06" ixy="-1.57542283433504E-07" ixz="2.71367446701359E-08" iyy="6.17952441557932E-06" iyz="1.58939319453383E-06" izz="1.4210192754512E-05" />
    </inertial>
    <visual>
      <origin rpy="0 0 0" xyz="0 0 0" />
      <geometry>
        <mesh filename="{SIMS_CORE}/meshes/piper/link8.dae" />
      </geometry>
      <material name="">
        <color rgba="0.792156862745098 0.819607843137255 0.933333333333333 1" />
      </material>
    </visual>
    <collision>
      <origin rpy="0 0 0" xyz="0 0 0" />
      <geometry>
        <mesh filename="{SIMS_CORE}/meshes/piper/link8.STL" />
      </geometry>
    </collision>
  </link>
  <joint name="left_joint7.2" type="prismatic">
    <origin rpy="-1.5708 0 3.1415926" xyz="0 0 0.13503" />
    <parent link="left_link6" />
    <child link="left_link7.2" />
    <axis xyz="0 0 1" />
    <limit effort="10" lower="-0.04" upper="0" velocity="1" />
  </joint>
  <link name="left_end_effector">
    <inertial>
      <origin rpy="0 0 0" xyz="0 0 0" />
      <mass value="0.001" />
      <inertia ixx="0.001" ixy="0" ixz="0" iyy="0.001" iyz="0" izz="0.001" />
    </inertial>
  </link>
  <joint name="left_end_effector_fixed_joint" type="fixed">
    <origin rpy="0 -1.5708 0" xyz="0 0 0.13503" />
    <parent link="left_link6" />
    <child link="left_end_effector" />
  </joint>
  <transmission name="left_tran1">
    <type>transmission_interface/SimpleTransmission</type>
    <joint name="left_joint1">
      <hardwareInterface>hardware_interface/PositionJointInterface</hardwareInterface>
    </joint>
    <actuator name="left_motor1">
      <hardwareInterface>hardware_interface/PositionJointInterface</hardwareInterface>
      <mechanicalReduction>1</mechanicalReduction>
    </actuator>
  </transmission>
  <transmission name="left_tran2">
    <type>transmission_interface/SimpleTransmission</type>
    <joint name="left_joint2">
      <hardwareInterface>hardware_interface/PositionJointInterface</hardwareInterface>
    </joint>
    <actuator name="left_motor2">
      <hardwareInterface>hardware_interface/PositionJointInterface</hardwareInterface>
      <mechanicalReduction>1</mechanicalReduction>
    </actuator>
  </transmission>
  <transmission name="left_tran3">
    <type>transmission_interface/SimpleTransmission</type>
    <joint name="left_joint3">
      <hardwareInterface>hardware_interface/PositionJointInterface</hardwareInterface>
    </joint>
    <actuator name="left_motor3">
      <hardwareInterface>hardware_interface/PositionJointInterface</hardwareInterface>
      <mechanicalReduction>1</mechanicalReduction>
    </actuator>
  </transmission>
  <transmission name="left_tran4">
    <type>transmission_interface/SimpleTransmission</type>
    <joint name="left_joint4">
      <hardwareInterface>hardware_interface/PositionJointInterface</hardwareInterface>
    </joint>
    <actuator name="left_motor4">
      <hardwareInterface>hardware_interface/PositionJointInterface</hardwareInterface>
      <mechanicalReduction>1</mechanicalReduction>
    </actuator>
  </transmission>
  <transmission name="left_tran5">
    <type>transmission_interface/SimpleTransmission</type>
    <joint name="left_joint5">
      <hardwareInterface>hardware_interface/PositionJointInterface</hardwareInterface>
    </joint>
    <actuator name="left_motor5">
      <hardwareInterface>hardware_interface/PositionJointInterface</hardwareInterface>
      <mechanicalReduction>1</mechanicalReduction>
    </actuator>
  </transmission>
  <transmission name="left_tran6">
    <type>transmission_interface/SimpleTransmission</type>
    <joint name="left_joint6">
      <hardwareInterface>hardware_interface/PositionJointInterface</hardwareInterface>
    </joint>
    <actuator name="left_motor6">
      <hardwareInterface>hardware_interface/PositionJointInterface</hardwareInterface>
      <mechanicalReduction>1</mechanicalReduction>
    </actuator>
  </transmission>
  <transmission name="left_tran7.1">
    <type>transmission_interface/SimpleTransmission</type>
    <joint name="left_joint7.1">
      <hardwareInterface>hardware_interface/PositionJointInterface</hardwareInterface>
    </joint>
    <actuator name="left_motor7.1">
      <hardwareInterface>hardware_interface/PositionJointInterface</hardwareInterface>
      <mechanicalReduction>1</mechanicalReduction>
    </actuator>
  </transmission>
  <transmission name="left_tran7.2">
    <type>transmission_interface/SimpleTransmission</type>
    <joint name="left_joint7.2">
      <hardwareInterface>hardware_interface/PositionJointInterface</hardwareInterface>
    </joint>
    <actuator name="left_motor7.2">
      <hardwareInterface>hardware_interface/PositionJointInterface</hardwareInterface>
      <mechanicalReduction>1</mechanicalReduction>
    </actuator>
  </transmission>
  <ros2_control name="right_PiperHardwareSystem" type="system">
    <hardware>
      <plugin>mock_components/GenericSystem</plugin>
    </hardware>
    <joint name="right_joint1">
      <command_interface name="position" />
      <command_interface name="effort" />
      <command_interface name="velocity" />
      <state_interface name="position" />
      <state_interface name="effort" />
      <state_interface name="velocity" />
      <param name="min">-2.618</param>
      <param name="max">2.618</param>
      <param name="type">revolute</param>
      <param name="max_effort">100</param>
    </joint>
    <joint name="right_joint2">
      <command_interface name="position" />
      <command_interface name="effort" />
      <command_interface name="velocity" />
      <state_interface name="position" />
      <state_interface name="effort" />
      <state_interface name="velocity" />
      <param name="min">0</param>
      <param name="max">3.14</param>
      <param name="type">revolute</param>
      <param name="max_effort">100</param>
    </joint>
    <joint name="right_joint3">
      <command_interface name="position" />
      <command_interface name="effort" />
      <command_interface name="velocity" />
      <state_interface name="position" />
      <state_interface name="effort" />
      <state_interface name="velocity" />
      <param name="min">-2.697</param>
      <param name="max">0</param>
      <param name="type">revolute</param>
      <param name="max_effort">100</param>
    </joint>
    <joint name="right_joint4">
      <command_interface name="position" />
      <command_interface name="effort" />
      <command_interface name="velocity" />
      <state_interface name="position" />
      <state_interface name="effort" />
      <state_interface name="velocity" />
      <param name="min">-1.832</param>
      <param name="max">1.832</param>
      <param name="type">revolute</param>
      <param name="max_effort">100</param>
    </joint>
    <joint name="right_joint5">
      <command_interface name="position" />
      <command_interface name="effort" />
      <command_interface name="velocity" />
      <state_interface name="position" />
      <state_interface name="effort" />
      <state_interface name="velocity" />
      <param name="min">-1.22</param>
      <param name="max">1.22</param>
      <param name="type">revolute</param>
      <param name="max_effort">100</param>
    </joint>
    <joint name="right_joint6">
      <command_interface name="position" />
      <command_interface name="effort" />
      <command_interface name="velocity" />
      <state_interface name="position" />
      <state_interface name="effort" />
      <state_interface name="velocity" />
      <param name="min">-3.14</param>
      <param name="max">3.14</param>
      <param name="type">revolute</param>
      <param name="max_effort">100</param>
    </joint>
    <joint name="right_joint7.1">
      <command_interface name="position" />
      <command_interface name="effort" />
      <command_interface name="velocity" />
      <state_interface name="position" />
      <state_interface name="effort" />
      <state_interface name="velocity" />
      <param name="min">0</param>
      <param name="max">0.04</param>
      <param name="type">prismatic</param>
      <param name="max_effort">10</param>
    </joint>
    <joint name="right_joint7.2">
      <command_interface name="position" />
      <command_interface name="effort" />
      <command_interface name="velocity" />
      <state_interface name="position" />
      <state_interface name="effort" />
      <state_interface name="velocity" />
      <param name="min">-0.04</param>
      <param name="max">0</param>
      <param name="type">prismatic</param>
      <param name="max_effort">10</param>
    </joint>
  </ros2_control>
  <link name="right_base_link">
    <inertial>
      <origin rpy="0 0 0" xyz="-0.00979274765955341 1.82905827587138E-06 0.0410100126360189" />
      <mass value="0.162548567403693" />
      <inertia ixx="0.000226596924525071" ixy="-7.33972270153965E-08" ixz="2.13249977802622E-06" iyy="0.000269444772561524" iyz="8.15169009611054E-09" izz="0.000222318258878636" />
    </inertial>
    <visual>
      <origin rpy="0 0 0" xyz="0 0 0" />
      <geometry>
        <mesh filename="{SIMS_CORE}/meshes/piper/base_link.dae" />
      </geometry>
      <material name="">
        <color rgba="0.792156862745098 0.819607843137255 0.933333333333333 1" />
      </material>
    </visual>
    <collision>
      <origin rpy="0 0 0" xyz="0 0 0" />
      <geometry>
        <mesh filename="{SIMS_CORE}/meshes/piper/base_link.STL" />
      </geometry>
    </collision>
  </link>
  <link name="right_link1">
    <inertial>
      <origin rpy="0 0 0" xyz="0.00131676031927024 0.000310288842008612 -0.00922874512303437" />
      <mass value="0.0978679932242825" />
      <inertia ixx="7.76684558296782E-05" ixy="1.09084650459924E-07" ixz="-1.9748053243241E-06" iyy="9.24967780161547E-05" iyz="9.91284646834582E-07" izz="8.24589062407807E-05" />
    </inertial>
    <visual>
      <origin rpy="0 0 0" xyz="0 0 0" />
      <geometry>
        <mesh filename="{SIMS_CORE}/meshes/piper/link1.dae" />
      </geometry>
      <material name="">
        <color rgba="0.792156862745098 0.819607843137255 0.933333333333333 1" />
      </material>
    </visual>
    <collision>
      <origin rpy="0 0 0" xyz="0 0 0" />
      <geometry>
        <mesh filename="{SIMS_CORE}/meshes/piper/link1.STL" />
      </geometry>
    </collision>
  </link>
  <joint name="right_joint1" type="revolute">
    <origin rpy="0 0 -1.5708" xyz="0 0 0.123" />
    <parent link="right_base_link" />
    <child link="right_link1" />
    <axis xyz="0 0 1" />
    <limit effort="100" lower="-2.618" upper="2.618" velocity="3" />
  </joint>
  <link name="right_link2">
    <inertial>
      <origin rpy="0 0 0" xyz="0.148793602378802 -0.00242026983944119 0.00175154638467948" />
      <mass value="0.290888938633388" />
      <inertia ixx="0.000148959640166183" ixy="-7.37750384371657E-05" ixz="-9.68688405196236E-07" iyy="0.00172800946632652" iyz="-1.09692225564224E-06" izz="0.0017754628344594" />
    </inertial>
    <visual>
      <origin rpy="0 0 0" xyz="0 0 0" />
      <geometry>
        <mesh filename="{SIMS_CORE}/meshes/piper/link2.dae" />
      </geometry>
      <material name="">
        <color rgba="0.792156862745098 0.819607843137255 0.933333333333333 1" />
      </material>
    </visual>
    <collision>
      <origin rpy="0 0 0" xyz="0 0 0" />
      <geometry>
        <mesh filename="{SIMS_CORE}/meshes/piper/link2.STL" />
      </geometry>
    </collision>
  </link>
  <joint name="right_joint2" type="revolute">
    <origin rpy="1.5708 0 -1.5708" xyz="0 0 0" />
    <parent link="right_link1" />
    <child link="right_link2" />
    <axis xyz="0 0 1" />
    <limit effort="100" lower="0" upper="3.14" velocity="3" />
  </joint>
  <link name="right_link3">
    <inertial>
      <origin rpy="0 0 0" xyz="-0.0996835215213704 0.0349477226691318 0.000508025815507312" />
      <mass value="0.290847697793211" />
      <inertia ixx="0.000107879011637167" ixy="2.92669521203626E-05" ixz="6.825922326238E-07" iyy="0.000214751671792086" iyz="-7.78469047878196E-07" izz="0.000241923439340319" />
    </inertial>
    <visual>
      <origin rpy="0 0 0" xyz="0 0 0" />
      <geometry>
        <mesh filename="{SIMS_CORE}/meshes/piper/link3.dae" />
      </geometry>
      <material name="">
        <color rgba="0.792156862745098 0.819607843137255 0.933333333333333 1" />
      </material>
    </visual>
    <collision>
      <origin rpy="0 0 0" xyz="0 0 0" />
      <geometry>
        <mesh filename="{SIMS_CORE}/meshes/piper/link3.STL" />
      </geometry>
    </collision>
  </link>
  <joint name="right_joint3" type="revolute">
    <origin rpy="0 0 0.10095" xyz="0.28358 0.028726 0" />
    <parent link="right_link2" />
    <child link="right_link3" />
    <axis xyz="0 0 1" />
    <limit effort="100" lower="-2.697" upper="0" velocity="3" />
  </joint>
  <link name="right_link4">
    <inertial>
      <origin rpy="0 0 0" xyz="0.000276464622387979 -0.00102803669324875 -0.00472830700561663" />
      <mass value="0.127087348341362" />
      <inertia ixx="3.82011730423416E-05" ixy="-4.92358350897513E-08" ixz="4.89589432973119E-08" iyy="4.87048555222578E-05" iyz="6.70802942500512E-08" izz="4.10592077565559E-05" />
    </inertial>
    <visual>
      <origin rpy="0 0 0" xyz="0 0 0" />
      <geometry>
        <mesh filename="{SIMS_CORE}/meshes/piper/link4.dae" />
      </geometry>
      <material name="">
        <color rgba="0.792156862745098 0.819607843137255 0.933333333333333 1" />
      </material>
    </visual>
    <collision>
      <origin rpy="0 0 0" xyz="0 0 0" />
      <geometry>
        <mesh filename="{SIMS_CORE}/meshes/piper/link4.STL" />
      </geometry>
    </collision>
  </link>
  <joint name="right_joint4" type="revolute">
    <origin rpy="-1.5708 0 1.3826" xyz="-0.24221 0.068514 0" />
    <parent link="right_link3" />
    <child link="right_link4" />
    <axis xyz="0 0 1" />
    <limit effort="100" lower="-1.832" upper="1.832" velocity="3" />
  </joint>
  <link name="right_link5">
    <inertial>
      <origin rpy="0 0 0" xyz="8.82262433516967E-05 0.0566829014808256 -0.00196119720482461" />
      <mass value="0.144711242639457" />
      <inertia ixx="4.39644313662493E-05" ixy="-3.59259686444846E-08" ixz="-1.89747741386183E-08" iyy="5.63173920951307E-05" iyz="-2.1540716689785E-07" izz="4.88713664675268E-05" />
    </inertial>
    <visual>
      <origin rpy="0 0 0" xyz="0 0 0" />
      <geometry>
        <mesh filename="{SIMS_CORE}/meshes/piper/link5.dae" />
      </geometry>
      <material name="">
        <color rgba="0.792156862745098 0.819607843137255 0.933333333333333 1" />
      </material>
    </visual>
    <collision>
      <origin rpy="0 0 0" xyz="0 0 0" />
      <geometry>
        <mesh filename="{SIMS_CORE}/meshes/piper/link5.STL" />
      </geometry>
    </collision>
  </link>
  <joint name="right_joint5" type="revolute">
    <origin rpy="1.5708 0 0" xyz="0 0 0" />
    <parent link="right_link4" />
    <child link="right_link5" />
    <axis xyz="0 0 1" />
    <limit effort="100" lower="-1.22" upper="1.22" velocity="3" />
  </joint>
  <link name="right_link6">
    <inertial>
      <origin rpy="0 0 0" xyz="0.00103120214523473 0.0121761387587524 0.0315480874960164" />
      <mass value="0.195187143240719" />
      <inertia ixx="6.43790256535539E-05" ixy="-1.2366166157046E-06" ixz="1.97664606328472E-07" iyy="0.000126146396374301" iyz="2.41157078516408E-06" izz="0.000154087076816444" />
    </inertial>
    <visual>
      <origin rpy="0 0 1.5708" xyz="0 0 0" />
      <geometry>
        <mesh filename="{SIMS_CORE}/meshes/piper/link6.dae" />
      </geometry>
      <material name="">
        <color rgba="0.792156862745098 0.819607843137255 0.933333333333333 1" />
      </material>
    </visual>
    <collision>
      <origin rpy="0 0 0" xyz="0 0 0" />
      <geometry>
        <mesh filename="{SIMS_CORE}/meshes/piper/link6_1.STL" />
      </geometry>
    </collision>
  </link>
  <joint name="right_joint6" type="revolute">
    <origin rpy="-1.5708 -3.1415926 0" xyz="0 0.091 0.0014165" />
    <parent link="right_link5" />
    <child link="right_link6" />
    <axis xyz="0 0 1" />
    <limit effort="100" lower="-3.14" upper="3.14" velocity="3" />
  </joint>
  <link name="right_link7.1">
    <inertial>
      <origin rpy="0 0 0" xyz="-0.000277778383727112 -0.0467673043650824 -0.00921029491873201" />
      <mass value="0.02648229234527" />
      <inertia ixx="9.99787479924589E-06" ixy="-1.57548495096104E-07" ixz="-2.71342775003487E-08" iyy="6.1795212293655E-06" iyz="-1.58939803580081E-06" izz="1.42102717246564E-05" />
    </inertial>
    <visual>
      <origin rpy="0 0 0" xyz="0 0 0" />
      <geometry>
        <mesh filename="{SIMS_CORE}/meshes/piper/link7.dae" />
      </geometry>
      <material name="">
        <color rgba="0.792156862745098 0.819607843137255 0.933333333333333 1" />
      </material>
    </visual>
    <collision>
      <origin rpy="0 0 0" xyz="0 0 0" />
      <geometry>
        <mesh filename="{SIMS_CORE}/meshes/piper/link7.STL" />
      </geometry>
    </collision>
  </link>
  <joint name="right_joint7.1" type="prismatic">
    <origin rpy="1.5708 0 3.1415926" xyz="0 0 0.13503" />
    <parent link="right_link6" />
    <child link="right_link7.1" />
    <axis xyz="0 0 -1" />
    <limit effort="10" lower="0" upper="0.04" velocity="1" />
  </joint>
  <link name="right_link7.2">
    <inertial>
      <origin rpy="0 0 0" xyz="0.000277816920932317 0.0467673824063769 -0.00921030054508036" />
      <mass value="0.0264822021416248" />
      <inertia ixx="9.99779119357223E-06" ixy="-1.57542283433504E-07" ixz="2.71367446701359E-08" iyy="6.17952441557932E-06" iyz="1.58939319453383E-06" izz="1.4210192754512E-05" />
    </inertial>
    <visual>
      <origin rpy="0 0 0" xyz="0 0 0" />
      <geometry>
        <mesh filename="{SIMS_CORE}/meshes/piper/link8.dae" />
      </geometry>
      <material name="">
        <color rgba="0.792156862745098 0.819607843137255 0.933333333333333 1" />
      </material>
    </visual>
    <collision>
      <origin rpy="0 0 0" xyz="0 0 0" />
      <geometry>
        <mesh filename="{SIMS_CORE}/meshes/piper/link8.STL" />
      </geometry>
    </collision>
  </link>
  <joint name="right_joint7.2" type="prismatic">
    <origin rpy="-1.5708 0 3.1415926" xyz="0 0 0.13503" />
    <parent link="right_link6" />
    <child link="right_link7.2" />
    <axis xyz="0 0 1" />
    <limit effort="10" lower="-0.04" upper="0" velocity="1" />
  </joint>
  <link name="right_end_effector">
    <inertial>
      <origin rpy="0 0 0" xyz="0 0 0" />
      <mass value="0.001" />
      <inertia ixx="0.001" ixy="0" ixz="0" iyy="0.001" iyz="0" izz="0.001" />
    </inertial>
  </link>
  <joint name="right_end_effector_fixed_joint" type="fixed">
    <origin rpy="0 -1.5708 0" xyz="0 0 0.13503" />
    <parent link="right_link6" />
    <child link="right_end_effector" />
  </joint>
  <transmission name="right_tran1">
    <type>transmission_interface/SimpleTransmission</type>
    <joint name="right_joint1">
      <hardwareInterface>hardware_interface/PositionJointInterface</hardwareInterface>
    </joint>
    <actuator name="right_motor1">
      <hardwareInterface>hardware_interface/PositionJointInterface</hardwareInterface>
      <mechanicalReduction>1</mechanicalReduction>
    </actuator>
  </transmission>
  <transmission name="right_tran2">
    <type>transmission_interface/SimpleTransmission</type>
    <joint name="right_joint2">
      <hardwareInterface>hardware_interface/PositionJointInterface</hardwareInterface>
    </joint>
    <actuator name="right_motor2">
      <hardwareInterface>hardware_interface/PositionJointInterface</hardwareInterface>
      <mechanicalReduction>1</mechanicalReduction>
    </actuator>
  </transmission>
  <transmission name="right_tran3">
    <type>transmission_interface/SimpleTransmission</type>
    <joint name="right_joint3">
      <hardwareInterface>hardware_interface/PositionJointInterface</hardwareInterface>
    </joint>
    <actuator name="right_motor3">
      <hardwareInterface>hardware_interface/PositionJointInterface</hardwareInterface>
      <mechanicalReduction>1</mechanicalReduction>
    </actuator>
  </transmission>
  <transmission name="right_tran4">
    <type>transmission_interface/SimpleTransmission</type>
    <joint name="right_joint4">
      <hardwareInterface>hardware_interface/PositionJointInterface</hardwareInterface>
    </joint>
    <actuator name="right_motor4">
      <hardwareInterface>hardware_interface/PositionJointInterface</hardwareInterface>
      <mechanicalReduction>1</mechanicalReduction>
    </actuator>
  </transmission>
  <transmission name="right_tran5">
    <type>transmission_interface/SimpleTransmission</type>
    <joint name="right_joint5">
      <hardwareInterface>hardware_interface/PositionJointInterface</hardwareInterface>
    </joint>
    <actuator name="right_motor5">
      <hardwareInterface>hardware_interface/PositionJointInterface</hardwareInterface>
      <mechanicalReduction>1</mechanicalReduction>
    </actuator>
  </transmission>
  <transmission name="right_tran6">
    <type>transmission_interface/SimpleTransmission</type>
    <joint name="right_joint6">
      <hardwareInterface>hardware_interface/PositionJointInterface</hardwareInterface>
    </joint>
    <actuator name="right_motor6">
      <hardwareInterface>hardware_interface/PositionJointInterface</hardwareInterface>
      <mechanicalReduction>1</mechanicalReduction>
    </actuator>
  </transmission>
  <transmission name="right_tran7.1">
    <type>transmission_interface/SimpleTransmission</type>
    <joint name="right_joint7.1">
      <hardwareInterface>hardware_interface/PositionJointInterface</hardwareInterface>
    </joint>
    <actuator name="right_motor7.1">
      <hardwareInterface>hardware_interface/PositionJointInterface</hardwareInterface>
      <mechanicalReduction>1</mechanicalReduction>
    </actuator>
  </transmission>
  <transmission name="right_tran7.2">
    <type>transmission_interface/SimpleTransmission</type>
    <joint name="right_joint7.2">
      <hardwareInterface>hardware_interface/PositionJointInterface</hardwareInterface>
    </joint>
    <actuator name="right_motor7.2">
      <hardwareInterface>hardware_interface/PositionJointInterface</hardwareInterface>
      <mechanicalReduction>1</mechanicalReduction>
    </actuator>
  </transmission>
  <material name="aluminum">
    <color rgba="0.5 0.5 0.5 1" />
  </material>
  <material name="plastic">
    <color rgba="0.1 0.1 0.1 1" />
  </material>
  <joint name="left_cam_joint" type="fixed">
    <origin rpy="0.0 -0.9 0.0" xyz="-0.05 0.0 0.035" />
    <parent link="left_link6" />
    <child link="left_cam_bottom_screw_frame" />
  </joint>
  <link name="left_cam_bottom_screw_frame" />
  <joint name="left_cam_link_joint" type="fixed">
    <origin rpy="0 0 0" xyz="0.01085 0.009 0.021" />
    <parent link="left_cam_bottom_screw_frame" />
    <child link="left_cam_link" />
  </joint>
  <link name="left_cam_link">
    <visual>
      <origin rpy="1.5707963267948966 0 1.5707963267948966" xyz="0.0038 -0.009 0" />
      <geometry>
        <mesh filename="{SIMS_CORE}/meshes/camera/d405.stl" scale="0.001 0.001 0.001" />
      </geometry>
      <material name="aluminum" />
    </visual>
    <collision>
      <origin rpy="0 0 0" xyz="-0.0078 -0.009 0" />
      <geometry>
        <box size="0.023 0.042 0.042" />
      </geometry>
    </collision>
    <inertial>
      <mass value="0.072" />
      <origin xyz="0 0 0" />
      <inertia ixx="0.003881243" ixy="0.0" ixz="0.0" iyy="0.000498940" iyz="0.0" izz="0.003879257" />
    </inertial>
  </link>
  <joint name="right_cam_joint" type="fixed">
    <origin rpy="0.0 -0.9 0.0" xyz="-0.05 0.0 0.035" />
    <parent link="right_link6" />
    <child link="right_cam_bottom_screw_frame" />
  </joint>
  <link name="right_cam_bottom_screw_frame" />
  <joint name="right_cam_link_joint" type="fixed">
    <origin rpy="0 0 0" xyz="0.01085 0.009 0.021" />
    <parent link="right_cam_bottom_screw_frame" />
    <child link="right_cam_link" />
  </joint>
  <link name="right_cam_link">
    <visual>
      <origin rpy="1.5707963267948966 0 1.5707963267948966" xyz="0.0038 -0.009 0" />
      <geometry>
        <mesh filename="{SIMS_CORE}/meshes/camera/d405.stl" scale="0.001 0.001 0.001" />
      </geometry>
      <material name="aluminum" />
    </visual>
    <collision>
      <origin rpy="0 0 0" xyz="-0.0078 -0.009 0" />
      <geometry>
        <box size="0.023 0.042 0.042" />
      </geometry>
    </collision>
    <inertial>
      <mass value="0.072" />
      <origin xyz="0 0 0" />
      <inertia ixx="0.003881243" ixy="0.0" ixz="0.0" iyy="0.000498940" iyz="0.0" izz="0.003879257" />
    </inertial>
  </link>
  <joint name="world_to_cam" type="fixed">
    <parent link="world" />
    <child link="center_cam" />
    <origin rpy="1.57 0.0 3.14" xyz="0.365 0.85 0.75" />
  </joint>
  <joint name="center_cam_joint" type="fixed">
    <origin rpy="0.0 0.4 0.0" xyz="0.0 0.0 0.0" />
    <parent link="center_cam" />
    <child link="center_cam_bottom_screw_frame" />
  </joint>
  <link name="center_cam_bottom_screw_frame" />
  <joint name="center_cam_link_joint" type="fixed">
    <origin rpy="0 0 0" xyz="0.011150000000000002 0.0475 0.0145" />
    <parent link="center_cam_bottom_screw_frame" />
    <child link="center_cam_link" />
  </joint>
  <link name="center_cam_link">
    <visual>
      <origin rpy="1.5707963267948966 0 1.5707963267948966" xyz="0.0046500000000000005 -0.0475 0" />
      <geometry>
        <mesh filename="{SIMS_CORE}/meshes/camera/d455.stl" scale="0.001 0.001 0.001" />
      </geometry>
      <material name="aluminum" />
    </visual>
    <collision>
      <origin rpy="0 0 0" xyz="-0.00845 -0.0475 0" />
      <geometry>
        <box size="0.026 0.124 0.029" />
      </geometry>
    </collision>
    <inertial>
      <mass value="0.072" />
      <origin xyz="0 0 0" />
      <inertia ixx="0.003881243" ixy="0.0" ixz="0.0" iyy="0.000498940" iyz="0.0" izz="0.003879257" />
    </inertial>
  </link>
</robot>
